Workbook

Sheet hotel_bookings_data
A1: Booking ID | B1: Booking Date | C1: Check-in Date | D1: Check-out Date | E1: Room Type | F1: Room Type ID | G1: Seasonal Adjustment | H1: Discount | I1: Discount Percentage | J1: Booking Channel | K1: Number of Rooms Booked | L1: Guest Type | M1: Loyalty Member | N1: Booking Status | O1: Days to Check-in | P1: Length of Stay | Q1: Room Rate | R1: Discount Amount | S1: O.T.A Commission Cost | T1: Loyalty Discount Amt | U1: Room Revenue | V1: Rooms Occupied for LOS
A2: 1003742 | B2: 45643 | C2: 45658 | D2: 45665 | E2: Suite | F2: 6 | G2: M | H2: 0 | I2: =H2/100 -> 0 | J2: Online | K2: 2 | L2: Corporate | M2: FALSE | N2: Checked Out | O2: =C2-B2 -> 15 | P2: =D2-C2 -> 7 | Q2: =IF(G2="B",VLOOKUP(F2,room_rates!$A$2:$G$8,3,FALSE),IF(G2="P",VLOOKUP(F2,room_rates!$A$2:$G$8,6,FALSE),IF(G2="M",VLOOKUP(F2,room_rates!$A$2:$G$8,7,FALSE),""))) -> 385 | R2: =Q2*(H2/100) -> 0 | S2: =IF(J2="Online Travel Agency",VLOOKUP(F2,room_rates!$A$2:$G$8,3,FALSE)*15%,0) -> 0 | T2: =IF(M2=TRUE, Q2*1%,0) -> 0 | U2: =(Q2-R2-S2-T2)*V2 -> 5390 | V2: =K2*P2 -> 14
A3: 1004212 | B3: 45653 | C3: 45658 | D3: 45659 | E3: Standard | F3: 1 | G3: M | H3: 5 | I3: =H3/100 -> 0.05 | J3: Online Travel Agency | K3: 1 | L3: Leisure | M3: FALSE | N3: Checked Out | O3: =C3-B3 -> 5 | P3: =D3-C3 -> 1 | Q3: =IF(G3="B",VLOOKUP(F3,room_rates!$A$2:$G$8,3,FALSE),IF(G3="P",VLOOKUP(F3,room_rates!$A$2:$G$8,6,FALSE),IF(G3="M",VLOOKUP(F3,room_rates!$A$2:$G$8,7,FALSE),""))) -> 132 | R3: =Q3*(H3/100) -> 6.6 | S3: =IF(J3="Online Travel Agency",VLOOKUP(F3,room_rates!$A$2:$G$8,3,FALSE)*15%,0) -> 18 | T3: =IF(M3=TRUE, Q3*1%,0) -> 0 | U3: =(Q3-R3-S3-T3)*V3 -> 107.4 | V3: =K3*P3 -> 1
A4: 1004256 | B4: 45658 | C4: 45658 | D4: 45664 | E4: Standard | F4: 2 | G4: M | H4: 5 | I4: =H4/100 -> 0.05 | J4: Direct | K4: 3 | L4: Corporate | M4: FALSE | N4: Checked Out | O4: =C4-B4 -> 0 | P4: =D4-C4 -> 6 | Q4: =IF(G4="B",VLOOKUP(F4,room_rates!$A$2:$G$8,3,FALSE),IF(G4="P",VLOOKUP(F4,room_rates!$A$2:$G$8,6,FALSE),IF(G4="M",VLOOKUP(F4,room_rates!$A$2:$G$8,7,FALSE),""))) -> 154 | R4: =Q4*(H4/100) -> 7.7 | S4: =IF(J4="Online Travel Agency",VLOOKUP(F4,room_rates!$A$2:$G$8,3,FALSE)*15%,0) -> 0 | T4: =IF(M4=TRUE, Q4*1%,0) -> 0 | U4: =(Q4-R4-S4-T4)*V4 -> 2633.4 | V4: =K4*P4 -> 18
A5: 1004284 | B5: 45658 | C5: 45658 | D5: 45659 | E5: Deluxe | F5: 5 | G5: M | H5: 0 | I5: =H5/100 -> 0 | J5: Direct | K5: 2 | L5: Corporate | M5: TRUE | N5: Checked Out | O5: =C5-B5 -> 0 | P5: =D5-C5 -> 1 | Q5: =IF(G5="B",VLOOKUP(F5,room_rates!$A$2:$G$8,3,FALSE),IF(G5="P",VLOOKUP(F5,room_rates!$A$2:$G$8,6,FALSE),IF(G5="M",VLOOKUP(F5,room_rates!$A$2:$G$8,7,FALSE),""))) -> 264 | R5: =Q5*(H5/100) -> 0 | S5: =IF(J5="Online Travel Agency",VLOOKUP(F5,room_rates!$A$2:$G$8,3,FALSE)*15%,0) -> 0 | T5: =IF(M5=TRUE, Q5*1%,0) -> 2.64 | U5: =(Q5-R5-S5-T5)*V5 -> 522.72 | V5: =K5*P5 -> 2
A6: 1004497 | B6: 45647 | C6: 45658 | D6: 45659 | E6: Deluxe | F6: 3 | G6: M | H6: 0 | I6: =H6/100 -> 0 | J6: Online Travel Agency | K6: 3 | L6: Leisure | M6: TRUE | N6: Checked Out | O6: =C6-B6 -> 11 | P6: =D6-C6 -> 1 | Q6: =IF(G6="B",VLOOKUP(F6,room_rates!$A$2:$G$8,3,FALSE),IF(G6="P",VLOOKUP(F6,room_rates!$A$2:$G$8,6,FALSE),IF(G6="M",VLOOKUP(F6,room_rates!$A$2:$G$8,7,FALSE),""))) -> 242 | R6: =Q6*(H6/100) -> 0 | S6: =IF(J6="Online Travel Agency",VLOOKUP(F6,room_rates!$A$2:$G$8,3,FALSE)*15%,0) -> 33 | T6: =IF(M6=TRUE, Q6*1%,0) -> 2.42 | U6: =(Q6-R6-S6-T6)*V6 -> 619.74 | V6: =K6*P6 -> 3
A7: 1004498 | B7: 45650 | C7: 45658 | D7: 45664 | E7: Standard | F7: 1 | G7: M | H7: 5 | I7: =H7/100 -> 0.05 | J7: Online Travel Agency | K7: 1 | L7: Leisure | M7: FALSE | N7: Checked Out | O7: =C7-B7 -> 8 | P7: =D7-C7 -> 6 | Q7: =IF(G7="B",VLOOKUP(F7,room_rates!$A$2:$G$8,3,FALSE),IF(G7="P",VLOOKUP(F7,room_rates!$A$2:$G$8,6,FALSE),IF(G7="M",VLOOKUP(F7,room_rates!$A$2:$G$8,7,FALSE),""))) -> 132 | R7: =Q7*(H7/100) -> 6.6 | S7: =IF(J7="Online Travel Agency",VLOOKUP(F7,room_rates!$A$2:$G$8,3,FALSE)*15%,0) -> 18 | T7: =IF(M7=TRUE, Q7*1%,0) -> 0 | U7: =(Q7-R7-S7-T7)*V7 -> 644.4 | V7: =K7*P7 -> 6
A8: 1004836 | B8: 45658 | C8: 45658 | D8: 45663 | E8: Standard | F8: 2 | G8: M | H8: 5 | I8: =H8/100 -> 0.05 | J8: Direct | K8: 3 | L8: Corporate | M8: FALSE | N8: Checked Out | O8: =C8-B8 -> 0 | P8: =D8-C8 -> 5 | Q8: =IF(G8="B",VLOOKUP(F8,room_rates!$A$2:$G$8,3,FALSE),IF(G8="P",VLOOKUP(F8,room_rates!$A$2:$G$8,6,FALSE),IF(G8="M",VLOOKUP(F8,room_rates!$A$2:$G$8,7,FALSE),""))) -> 154 | R8: =Q8*(H8/100) -> 7.7 | S8: =IF(J8="Online Travel Agency",VLOOKUP(F8,room_rates!$A$2:$G$8,3,FALSE)*15%,0) -> 0 | T8: =IF(M8=TRUE, Q8*1%,0) -> 0 | U8: =(Q8-R8-S8-T8)*V8 -> 2194.5 | V8: =K8*P8 -> 15
A9: 1005224 | B9: 45631 | C9: 45658 | D9: 45660 | E9: Standard | F9: 1 | G9: M | H9: 5 | I9: =H9/100 -> 0.05 | J9: Online | K9: 1 | L9: Leisure | M9: FALSE | N9: Checked Out | O9: =C9-B9 -> 27 | P9: =D9-C9 -> 2 | Q9: =IF(G9="B",VLOOKUP(F9,room_rates!$A$2:$G$8,3,FALSE),IF(G9="P",VLOOKUP(F9,room_rates!$A$2:$G$8,6,FALSE),IF(G9="M",VLOOKUP(F9,room_rates!$A$2:$G$8,7,FALSE),""))) -> 132 | R9: =Q9*(H9/100) -> 6.6 | S9: =IF(J9="Online Travel Agency",VLOOKUP(F9,room_rates!$A$2:$G$8,3,FALSE)*15%,0) -> 0 | T9: =IF(M9=TRUE, Q9*1%,0) -> 0 | U9: =(Q9-R9-S9-T9)*V9 -> 250.8 | V9: =K9*P9 -> 2
A10: 1005469 | B10: 45658 | C10: 45658 | D10: 45663 | E10: Standard | F10: 1 | G10: M | H10: 5 | I10: =H10/100 -> 0.05 | J10: Direct | K10: 2 | L10: Leisure | M10: FALSE | N10: Checked Out | O10: =C10-B10 -> 0 | P10: =D10-C10 -> 5 | Q10: =IF(G10="B",VLOOKUP(F10,room_rates!$A$2:$G$8,3,FALSE),IF(G10="P",VLOOKUP(F10,room_rates!$A$2:$G$8,6,FALSE),IF(G10="M",VLOOKUP(F10,room_rates!$A$2:$G$8,7,FALSE),""))) -> 132 | R10: =Q10*(H10/100) -> 6.6 | S10: =IF(J10="Online Travel Agency",VLOOKUP(F10,room_rates!$A$2:$G$8,3,FALSE)*15%,0) -> 0 | T10: =IF(M10=TRUE, Q10*1%,0) -> 0 | U10: =(Q10-R10-S10-T10)*V10 -> 1254 | V10: =K10*P10 -> 10
A11: 1005491 | B11: 45640 | C11: 45658 | D11: 45660 | E11: Deluxe | F11: 3 | G11: M | H11: 0 | I11: =H11/100 -> 0 | J11: Online Travel Agency | K11: 3 | L11: Corporate | M11: FALSE | N11: Checked Out | O11: =C11-B11 -> 18 | P11: =D11-C11 -> 2 | Q11: =IF(G11="B",VLOOKUP(F11,room_rates!$A$2:$G$8,3,FALSE),IF(G11="P",VLOOKUP(F11,room_rates!$A$2:$G$8,6,FALSE),IF(G11="M",VLOOKUP(F11,room_rates!$A$2:$G$8,7,FALSE),""))) -> 242 | R11: =Q11*(H11/100) -> 0 | S11: =IF(J11="Online Travel Agency",VLOOKUP(F11,room_rates!$A$2:$G$8,3,FALSE)*15%,0) -> 33 | T11: =IF(M11=TRUE, Q11*1%,0) -> 0 | U11: =(Q11-R11-S11-T11)*V11 -> 1254 | V11: =K11*P11 -> 6
A12: 1005546 | B12: 45644 | C12: 45658 | D12: 45663 | E12: Deluxe | F12: 3 | G12: M | H12: 0 | I12: =H12/100 -> 0 | J12: Online | K12: 1 | L12: Corporate | M12: FALSE | N12: Checked Out | O12: =C12-B12 -> 14 | P12: =D12-C12 -> 5 | Q12: =IF(G12="B",VLOOKUP(F12,room_rates!$A$2:$G$8,3,FALSE),IF(G12="P",VLOOKUP(F12,room_rates!$A$2:$G$8,6,FALSE),IF(G12="M",VLOOKUP(F12,room_rates!$A$2:$G$8,7,FALSE),""))) -> 242 | R12: =Q12*(H12/100) -> 0 | S12: =IF(J12="Online Travel Agency",VLOOKUP(F12,room_rates!$A$2:$G$8,3,FALSE)*15%,0) -> 0 | T12: =IF(M12=TRUE, Q12*1%,0) -> 0 | U12: =(Q12-R12-S12-T12)*V12 -> 1210 | V12: =K12*P12 -> 5
A13: 1005586 | B13: 45641 | C13: 45658 | D13: 45665 | E13: Standard | F13: 1 | G13: M | H13: 5 | I13: =H13/100 -> 0.05 | J13: Online Travel Agency | K13: 1 | L13: Corporate | M13: TRUE | N13: Checked Out | O13: =C13-B13 -> 17 | P13: =D13-C13 -> 7 | Q13: =IF(G13="B",VLOOKUP(F13,room_rates!$A$2:$G$8,3,FALSE),IF(G13="P",VLOOKUP(F13,room_rates!$A$2:$G$8,6,FALSE),IF(G13="M",VLOOKUP(F13,room_rates!$A$2:$G$8,7,FALSE),""))) -> 132 | R13: =Q13*(H13/100) -> 6.6 | S13: =IF(J13="Online Travel Agency",VLOOKUP(F13,room_rates!$A$2:$G$8,3,FALSE)*15%,0) -> 18 | T13: =IF(M13=TRUE, Q13*1%,0) -> 1.32 | U13: =(Q13-R13-S13-T13)*V13 -> 742.56 | V13: =K13*P13 -> 7
... A526: 1006810 | B526: 45688 | C526: 45688 | D526: 45691 | E526: Deluxe | F526: 3 | G526: M | H526: 0 | I526: =H526/100 -> 0 | J526: Direct | K526: 1 | L526: Corporate | M526: FALSE | N526: Checked Out | O526: =C526-B526 -> 0 | P526: =D526-C526 -> 3 | Q526: =IF(G526="B",VLOOKUP(F526,room_rates!$A$2:$G$8,3,FALSE),IF(G526="P",VLOOKUP(F526,room_rates!$A$2:$G$8,6,FALSE),IF(G526="M",VLOOKUP(F526,room_rates!$A$2:$G$8,7,FALSE),""))) -> 242 | R526: =Q526*(H526/100) -> 0 | S526: =IF(J526="Online Travel Agency",VLOOKUP(F526,room_rates!$A$2:$G$8,3,FALSE)*15%,0) -> 0 | T526: =IF(M526=TRUE, Q526*1%,0) -> 0 | U526: =(Q526-R526-S526-T526)*V526 -> 726 | V526: =K526*P526 -> 3
A527: 1007081 | B527: 45688 | C527: 45688 | E527: Standard | F527: 2 | H527: 0 | J527: Online | K527: 1 | L527: Leisure | N527: Cancelled
A528: 1005633 | B528: 45678 | C528: 45689 | D528: 45691 | E528: Deluxe | F528: 3 | G528: B | H528: 0 | I528: =H528/100 -> 0 | J528: Online Travel Agency | K528: 2 | L528: Corporate | M528: FALSE | N528: Checked Out | O528: =C528-B528 -> 11 | P528: =D528-C528 -> 2 | Q528: =IF(G528="B",VLOOKUP(F528,room_rates!$A$2:$G$8,3,FALSE),IF(G528="P",VLOOKUP(F528,room_rates!$A$2:$G$8,6,FALSE),IF(G528="M",VLOOKUP(F528,room_rates!$A$2:$G$8,7,FALSE),""))) -> 220 | R528: =Q528*(H528/100) -> 0 | S528: =IF(J528="Online Travel Agency",VLOOKUP(F528,room_rates!$A$2:$G$8,3,FALSE)*15%,0) -> 33 | T528: =IF(M528=TRUE, Q528*1%,0) -> 0 | U528: =(Q528-R528-S528-T528)*V528 -> 748 | V528: =K528*P528 -> 4
A529: 1005702 | B529: 45669 | C529: 45689 | D529: 45691 | E529: Standard | F529: 2 | G529: B | H529: 0 | I529: =H529/100 -> 0 | J529: Online | K529: 2 | L529: Corporate | M529: FALSE | N529: Checked Out | O529: =C529-B529 -> 20 | P529: =D529-C529 -> 2 | Q529: =IF(G529="B",VLOOKUP(F529,room_rates!$A$2:$G$8,3,FALSE),IF(G529="P",VLOOKUP(F529,room_rates!$A$2:$G$8,6,FALSE),IF(G529="M",VLOOKUP(F529,room_rates!$A$2:$G$8,7,FALSE),""))) -> 140 | R529: =Q529*(H529/100) -> 0 | S529: =IF(J529="Online Travel Agency",VLOOKUP(F529,room_rates!$A$2:$G$8,3,FALSE)*15%,0) -> 0 | T529: =IF(M529=TRUE, Q529*1%,0) -> 0 | U529: =(Q529-R529-S529-T529)*V529 -> 560 | V529: =K529*P529 -> 4
A530: 1006283 | B530: 45675 | C530: 45689 | D530: 45690 | E530: Deluxe | F530: 3 | G530: B | H530: 0 | I530: =H530/100 -> 0 | J530: Online | K530: 3 | L530: Corporate | M530: FALSE | N530: Checked Out | O530: =C530-B530 -> 14 | P530: =D530-C530 -> 1 | Q530: =IF(G530="B",VLOOKUP(F530,room_rates!$A$2:$G$8,3,FALSE),IF(G530="P",VLOOKUP(F530,room_rates!$A$2:$G$8,6,FALSE),IF(G530="M",VLOOKUP(F530,room_rates!$A$2:$G$8,7,FALSE),""))) -> 220 | R530: =Q530*(H530/100) -> 0 | S530: =IF(J530="Online Travel Agency",VLOOKUP(F530,room_rates!$A$2:$G$8,3,FALSE)*15%,0) -> 0 | T530: =IF(M530=TRUE, Q530*1%,0) -> 0 | U530: =(Q530-R530-S530-T530)*V530 -> 660 | V530: =K530*P530 -> 3
A531: 1006430 | B531: 45689 | C531: 45689 | D531: 45691 | E531: Standard | F531: 1 | G531: B | H531: 0 | I531: =H531/100 -> 0 | J531: Direct | K531: 2 | L531: Corporate | M531: FALSE | N531: Checked Out | O531: =C531-B531 -> 0 | P531: =D531-C531 -> 2 | Q531: =IF(G531="B",VLOOKUP(F531,room_rates!$A$2:$G$8,3,FALSE),IF(G531="P",VLOOKUP(F531,room_rates!$A$2:$G$8,6,FALSE),IF(G531="M",VLOOKUP(F531,room_rates!$A$2:$G$8,7,FALSE),""))) -> 120 | R531: =Q531*(H531/100) -> 0 | S531: =IF(J531="Online Travel Agency",VLOOKUP(F531,room_rates!$A$2:$G$8,3,FALSE)*15%,0) -> 0 | T531: =IF(M531=TRUE, Q531*1%,0) -> 0 | U531: =(Q531-R531-S531-T531)*V531 -> 480 | V531: =K531*P531 -> 4
A532: 1006448 | B532: 45659 | C532: 45689 | D532: 45691 | E532: Standard | F532: 1 | G532: B | H532: 0 | I532: =H532/100 -> 0 | J532: Online | K532: 1 | L532: Leisure | M532: FALSE | N532: Checked Out | O532: =C532-B532 -> 30 | P532: =D532-C532 -> 2 | Q532: =IF(G532="B",VLOOKUP(F532,room_rates!$A$2:$G$8,3,FALSE),IF(G532="P",VLOOKUP(F532,room_rates!$A$2:$G$8,6,FALSE),IF(G532="M",VLOOKUP(F532,room_rates!$A$2:$G$8,7,FALSE),""))) -> 120 | R532: =Q532*(H532/100) -> 0 | S532: =IF(J532="Online Travel Agency",VLOOKUP(F532,room_rates!$A$2:$G$8,3,FALSE)*15%,0) -> 0 | T532: =IF(M532=TRUE, Q532*1%,0) -> 0 | U532: =(Q532-R532-S532-T532)*V532 -> 240 | V532: =K532*P532 -> 2
A533: 1006631 | B533: 45671 | C533: 45689 | D533: 45690 | E533: Standard | F533: 1 | G533: B | H533: 0 | I533: =H533/100 -> 0 | J533: Online Travel Agency | K533: 2 | L533: Leisure | M533: FALSE | N533: Checked Out | O533: =C533-B533 -> 18 | P533: =D533-C533 -> 1 | Q533: =IF(G533="B",VLOOKUP(F533,room_rates!$A$2:$G$8,3,FALSE),IF(G533="P",VLOOKUP(F533,room_rates!$A$2:$G$8,6,FALSE),IF(G533="M",VLOOKUP(F533,room_rates!$A$2:$G$8,7,FALSE),""))) -> 120 | R533: =Q533*(H533/100) -> 0 | S533: =IF(J533="Online Travel Agency",VLOOKUP(F533,room_rates!$A$2:$G$8,3,FALSE)*15%,0) -> 18 | T533: =IF(M533=TRUE, Q533*1%,0) -> 0 | U533: =(Q533-R533-S533-T533)*V533 -> 204 | V533: =K533*P533 -> 2
A534: 1006904 | B534: 45671 | C534: 45689 | E534: Deluxe | F534: 3 | H534: 0 | J534: Online | K534: 1 | L534: Leisure | N534: Cancelled
A535: 1006050 | B535: 45690 | C535: 45690 | D535: 45692 | E535: Deluxe | F535: 3 | G535: B | H535: 0 | I535: =H535/100 -> 0 | J535: Direct | K535: 3 | L535: Corporate | M535: FALSE | N535: Checked Out | O535: =C535-B535 -> 0 | P535: =D535-C535 -> 2 | Q535: =IF(G535="B",VLOOKUP(F535,room_rates!$A$2:$G$8,3,FALSE),IF(G535="P",VLOOKUP(F535,room_rates!$A$2:$G$8,6,FALSE),IF(G535="M",VLOOKUP(F535,room_rates!$A$2:$G$8,7,FALSE),""))) -> 220 | R535: =Q535*(H535/100) -> 0 | S535: =IF(J535="Online Travel Agency",VLOOKUP(F535,room_rates!$A$2:$G$8,3,FALSE)*15%,0) -> 0 | T535: =IF(M535=TRUE, Q535*1%,0) -> 0 | U535: =(Q535-R535-S535-T535)*V535 -> 1320 | V535: =K535*P535 -> 6
A536: 1006203 | B536: 45690 | C536: 45690 | D536: 45692 | E536: Deluxe | F536: 3 | G536: B | H536: 0 | I536: =H536/100 -> 0 | J536: Direct | K536: 3 | L536: Corporate | M536: FALSE | N536: Checked Out | O536: =C536-B536 -> 0 | P536: =D536-C536 -> 2 | Q536: =IF(G536="B",VLOOKUP(F536,room_rates!$A$2:$G$8,3,FALSE),IF(G536="P",VLOOKUP(F536,room_rates!$A$2:$G$8,6,FALSE),IF(G536="M",VLOOKUP(F536,room_rates!$A$2:$G$8,7,FALSE),""))) -> 220 | R536: =Q536*(H536/100) -> 0 | S536: =IF(J536="Online Travel Agency",VLOOKUP(F536,room_rates!$A$2:$G$8,3,FALSE)*15%,0) -> 0 | T536: =IF(M536=TRUE, Q536*1%,0) -> 0 | U536: =(Q536-R536-S536-T536)*V536 -> 1320 | V536: =K536*P536 -> 6
A537: 1006417 | B537: 45670 | C537: 45690 | D537: 45691 | E537: Standard | F537: 1 | G537: B | H537: 0 | I537: =H537/100 -> 0 | J537: Online Travel Agency | K537: 2 | L537: Leisure | M537: FALSE | N537: Checked Out | O537: =C537-B537 -> 20 | P537: =D537-C537 -> 1 | Q537: =IF(G537="B",VLOOKUP(F537,room_rates!$A$2:$G$8,3,FALSE),IF(G537="P",VLOOKUP(F537,room_rates!$A$2:$G$8,6,FALSE),IF(G537="M",VLOOKUP(F537,room_rates!$A$2:$G$8,7,FALSE),""))) -> 120 | R537: =Q537*(H537/100) -> 0 | S537: =IF(J537="Online Travel Agency",VLOOKUP(F537,room_rates!$A$2:$G$8,3,FALSE)*15%,0) -> 18 | T537: =IF(M537=TRUE, Q537*1%,0) -> 0 | U537: =(Q537-R537-S537-T537)*V537 -> 204 | V537: =K537*P537 -> 2
A538: 1005889 | B538: 45659 | C538: 45691 | D538: 45694 | E538: Deluxe | F538: 5 | G538: B | H538: 0 | I538: =H538/100 -> 0 | J538: Online | K538: 3 | L538: Corporate | M538: FALSE | N538: Checked Out | O538: =C538-B538 -> 32 | P538: =D538-C538 -> 3 | Q538: =IF(G538="B",VLOOKUP(F538,room_rates!$A$2:$G$8,3,FALSE),IF(G538="P",VLOOKUP(F538,room_rates!$A$2:$G$8,6,FALSE),IF(G538="M",VLOOKUP(F538,room_rates!$A$2:$G$8,7,FALSE),""))) -> 240 | R538: =Q538*(H538/100) -> 0 | S538: =IF(J538="Online Travel Agency",VLOOKUP(F538,room_rates!$A$2:$G$8,3,FALSE)*15%,0) -> 0 | T538: =IF(M538=TRUE, Q538*1%,0) -> 0 | U538: =(Q538-R538-S538-T538)*V538 -> 2160 | V538: =K538*P538 -> 9
A539: 1006245 | B539: 45669 | C539: 45691 | D539: 45693 | E539: Standard | F539: 1 | G539: B | H539: 0 | I539: =H539/100 -> 0 | J539: Online | K539: 2 | L539: Leisure | M539: FALSE | N539: Checked Out | O539: =C539-B539 -> 22 | P539: =D539-C539 -> 2 | Q539: =IF(G539="B",VLOOKUP(F539,room_rates!$A$2:$G$8,3,FALSE),IF(G539="P",VLOOKUP(F539,room_rates!$A$2:$G$8,6,FALSE),IF(G539="M",VLOOKUP(F539,room_rates!$A$2:$G$8,7,FALSE),""))) -> 120 | R539: =Q539*(H539/100) -> 0 | S539: =IF(J539="Online Travel Agency",VLOOKUP(F539,room_rates!$A$2:$G$8,3,FALSE)*15%,0) -> 0 | T539: =IF(M539=TRUE, Q539*1%,0) -> 0 | U539: =(Q539-R539-S539-T539)*V539 -> 480 | V539: =K539*P539 -> 4
A540: 1006787 | B540: 45689 | C540: 45691 | D540: 45694 | E540: Deluxe | F540: 3 | G540: B | H540: 0 | I540: =H540/100 -> 0 | J540: Online | K540: 2 | L540: Leisure | M540: FALSE | N540: Checked Out | O540: =C540-B540 -> 2 | P540: =D540-C540 -> 3 | Q540: =IF(G540="B",VLOOKUP(F540,room_rates!$A$2:$G$8,3,FALSE),IF(G540="P",VLOOKUP(F540,room_rates!$A$2:$G$8,6,FALSE),IF(G540="M",VLOOKUP(F540,room_rates!$A$2:$G$8,7,FALSE),""))) -> 220 | R540: =Q540*(H540/100) -> 0 | S540: =IF(J540="Online Travel Agency",VLOOKUP(F540,room_rates!$A$2:$G$8,3,FALSE)*15%,0) -> 0 | T540: =IF(M540=TRUE, Q540*1%,0) -> 0 | U540: =(Q540-R540-S540-T540)*V540 -> 1320 | V540: =K540*P540 -> 6
A541: 1007058 | B541: 45689 | C541: 45691 | E541: Standard | F541: 1 | H541: 0 | J541: Online | K541: 2 | L541: Corporate | N541: Cancelled
A542: 1003016 | B542: 45679 | C542: 45692 | D542: 45698 | E542: Suite | F542: 7 | G542: B | H542: 0 | I542: =H542/100 -> 0 | J542: Online | K542: 1 | L542: Leisure | M542: FALSE | N542: Checked Out | O542: =C542-B542 -> 13 | P542: =D542-C542 -> 6 | Q542: =IF(G542="B",VLOOKUP(F542,room_rates!$A$2:$G$8,3,FALSE),IF(G542="P",VLOOKUP(F542,room_rates!$A$2:$G$8,6,FALSE),IF(G542="M",VLOOKUP(F542,room_rates!$A$2:$G$8,7,FALSE),""))) -> 450 | R542: =Q542*(H542/100) -> 0 | S542: =IF(J542="Online Travel Agency",VLOOKUP(F542,room_rates!$A$2:$G$8,3,FALSE)*15%,0) -> 0 | T542: =IF(M542=TRUE, Q542*1%,0) -> 0 | U542: =(Q542-R542-S542-T542)*V542 -> 2700 | V542: =K542*P542 -> 6
A543: 1005737 | B543: 45676 | C543: 45692 | D543: 45693 | E543: Standard | F543: 1 | G543: B | H543: 0 | I543: =H543/100 -> 0 | J543: Online Travel Agency | K543: 2 | L543: Leisure | M543: FALSE | N543: Checked Out | O543: =C543-B543 -> 16 | P543: =D543-C543 -> 1 | Q543: =IF(G543="B",VLOOKUP(F543,room_rates!$A$2:$G$8,3,FALSE),IF(G543="P",VLOOKUP(F543,room_rates!$A$2:$G$8,6,FALSE),IF(G543="M",VLOOKUP(F543,room_rates!$A$2:$G$8,7,FALSE),""))) -> 120 | R543: =Q543*(H543/100) -> 0 | S543: =IF(J543="Online Travel Agency",VLOOKUP(F543,room_rates!$A$2:$G$8,3,FALSE)*15%,0) -> 18 | T543: =IF(M543=TRUE, Q543*1%,0) -> 0 | U543: =(Q543-R543-S543-T543)*V543 -> 204 | V543: =K543*P543 -> 2
A544: 1005826 | B544: 45692 | C544: 45692 | D544: 45694 | E544: Deluxe | F544: 3 | G544: B | H544: 0 | I544: =H544/100 -> 0 | J544: Direct | K544: 1 | L544: Leisure | M544: TRUE | N544: Checked Out | O544: =C544-B544 -> 0 | P544: =D544-C544 -> 2 | Q544: =IF(G544="B",VLOOKUP(F544,room_rates!$A$2:$G$8,3,FALSE),IF(G544="P",VLOOKUP(F544,room_rates!$A$2:$G$8,6,FALSE),IF(G544="M",VLOOKUP(F544,room_rates!$A$2:$G$8,7,FALSE),""))) -> 220 | R544: =Q544*(H544/100) -> 0 | S544: =IF(J544="Online Travel Agency",VLOOKUP(F544,room_rates!$A$2:$G$8,3,FALSE)*15%,0) -> 0 | T544: =IF(M544=TRUE, Q544*1%,0) -> 2.2 | U544: =(Q544-R544-S544-T544)*V544 -> 435.6 | V544: =K544*P544 -> 2
A545: 1006103 | B545: 45690 | C545: 45692 | D545: 45694 | E545: Standard | F545: 1 | G545: B | H545: 0 | I545: =H545/100 -> 0 | J545: Online | K545: 2 | L545: Leisure | M545: FALSE | N545: Checked Out | O545: =C545-B545 -> 2 | P545: =D545-C545 -> 2 | Q545: =IF(G545="B",VLOOKUP(F545,room_rates!$A$2:$G$8,3,FALSE),IF(G545="P",VLOOKUP(F545,room_rates!$A$2:$G$8,6,FALSE),IF(G545="M",VLOOKUP(F545,room_rates!$A$2:$G$8,7,FALSE),""))) -> 120 | R545: =Q545*(H545/100) -> 0 | S545: =IF(J545="Online Travel Agency",VLOOKUP(F545,room_rates!$A$2:$G$8,3,FALSE)*15%,0) -> 0 | T545: =IF(M545=TRUE, Q545*1%,0) -> 0 | U545: =(Q545-R545-S545-T545)*V545 -> 480 | V545: =K545*P545 -> 4
A546: 1006155 | B546: 45667 | C546: 45692 | D546: 45693 | E546: Deluxe | F546: 3 | G546: B | H546: 0 | I546: =H546/100 -> 0 | J546: Online | K546: 1 | L546: Corporate | M546: FALSE | N546: Checked Out | O546: =C546-B546 -> 25 | P546: =D546-C546 -> 1 | Q546: =IF(G546="B",VLOOKUP(F546,room_rates!$A$2:$G$8,3,FALSE),IF(G546="P",VLOOKUP(F546,room_rates!$A$2:$G$8,6,FALSE),IF(G546="M",VLOOKUP(F546,room_rates!$A$2:$G$8,7,FALSE),""))) -> 220 | R546: =Q546*(H546/100) -> 0 | S546: =IF(J546="Online Travel Agency",VLOOKUP(F546,room_rates!$A$2:$G$8,3,FALSE)*15%,0) -> 0 | T546: =IF(M546=TRUE, Q546*1%,0) -> 0 | U546: =(Q546-R546-S546-T546)*V546 -> 220 | V546: =K546*P546 -> 1
A547: 1006761 | B547: 45684 | C547: 45692 | D547: 45694 | E547: Deluxe | F547: 3 | G547: B | H547: 0 | I547: =H547/100 -> 0 | J547: Online | K547: 1 | L547: Leisure | M547: FALSE | N547: Checked Out | O547: =C547-B547 -> 8 | P547: =D547-C547 -> 2 | Q547: =IF(G547="B",VLOOKUP(F547,room_rates!$A$2:$G$8,3,FALSE),IF(G547="P",VLOOKUP(F547,room_rates!$A$2:$G$8,6,FALSE),IF(G547="M",VLOOKUP(F547,room_rates!$A$2:$G$8,7,FALSE),""))) -> 220 | R547: =Q547*(H547/100) -> 0 | S547: =IF(J547="Online Travel Agency",VLOOKUP(F547,room_rates!$A$2:$G$8,3,FALSE)*15%,0) -> 0 | T547: =IF(M547=TRUE, Q547*1%,0) -> 0 | U547: =(Q547-R547-S547-T547)*V547 -> 440 | V547: =K547*P547 -> 2
A548: 1007032 | B548: 45684 | C548: 45692 | E548: Deluxe | F548: 3 | H548: 0 | J548: Online | K548: 2 | L548: Leisure | N548: Cancelled
A549: 1002302 | B549: 45683 | C549: 45693 | D549: 45696 | E549: Standard | F549: 2 | G549: B | H549: 0 | I549: =H549/100 -> 0 | J549: Online Travel Agency | K549: 2 | L549: Corporate | M549: FALSE | N549: Checked Out | O549: =C549-B549 -> 10 | P549: =D549-C549 -> 3 | Q549: =IF(G549="B",VLOOKUP(F549,room_rates!$A$2:$G$8,3,FALSE),IF(G549="P",VLOOKUP(F549,room_rates!$A$2:$G$8,6,FALSE),IF(G549="M",VLOOKUP(F549,room_rates!$A$2:$G$8,7,FALSE),""))) -> 140 | R549: =Q549*(H549/100) -> 0 | S549: =IF(J549="Online Travel Agency",VLOOKUP(F549,room_rates!$A$2:$G$8,3,FALSE)*15%,0) -> 21 | T549: =IF(M549=TRUE, Q549*1%,0) -> 0 | U549: =(Q549-R549-S549-T549)*V549 -> 714 | V549: =K549*P549 -> 6
A550: 1002355 | B550: 45674 | C550: 45693 | D550: 45696 | E550: Standard | F550: 2 | G550: B | H550: 0 | I550: =H550/100 -> 0 | J550: Online | K550: 3 | L550: Corporate | M550: FALSE | N550: Checked Out | O550: =C550-B550 -> 19 | P550: =D550-C550 -> 3 | Q550: =IF(G550="B",VLOOKUP(F550,room_rates!$A$2:$G$8,3,FALSE),IF(G550="P",VLOOKUP(F550,room_rates!$A$2:$G$8,6,FALSE),IF(G550="M",VLOOKUP(F550,room_rates!$A$2:$G$8,7,FALSE),""))) -> 140 | R550: =Q550*(H550/100) -> 0 | S550: =IF(J550="Online Travel Agency",VLOOKUP(F550,room_rates!$A$2:$G$8,3,FALSE)*15%,0) -> 0 | T550: =IF(M550=TRUE, Q550*1%,0) -> 0 | U550: =(Q550-R550-S550-T550)*V550 -> 1260 | V550: =K550*P550 -> 9
A551: 1002653 | B551: 45675 | C551: 45693 | D551: 45698 | E551: Standard | F551: 1 | G551: B | H551: 0 | I551: =H551/100 -> 0 | J551: Online | K551: 2 | L551: Leisure | M551: FALSE | N551: Checked Out | O551: =C551-B551 -> 18 | P551: =D551-C551 -> 5 | Q551: =IF(G551="B",VLOOKUP(F551,room_rates!$A$2:$G$8,3,FALSE),IF(G551="P",VLOOKUP(F551,room_rates!$A$2:$G$8,6,FALSE),IF(G551="M",VLOOKUP(F551,room_rates!$A$2:$G$8,7,FALSE),""))) -> 120 | R551: =Q551*(H551/100) -> 0 | S551: =IF(J551="Online Travel Agency",VLOOKUP(F551,room_rates!$A$2:$G$8,3,FALSE)*15%,0) -> 0 | T551: =IF(M551=TRUE, Q551*1%,0) -> 0 | U551: =(Q551-R551-S551-T551)*V551 -> 1200 | V551: =K551*P551 -> 10
A552: 1002854 | B552: 45693 | C552: 45693 | D552: 45695 | E552: Standard | F552: 1 | G552: B | H552: 0 | I552: =H552/100 -> 0 | J552: Direct | K552: 1 | L552: Leisure | M552: FALSE | N552: Checked Out | O552: =C552-B552 -> 0 | P552: =D552-C552 -> 2 | Q552: =IF(G552="B",VLOOKUP(F552,room_rates!$A$2:$G$8,3,FALSE),IF(G552="P",VLOOKUP(F552,room_rates!$A$2:$G$8,6,FALSE),IF(G552="M",VLOOKUP(F552,room_rates!$A$2:$G$8,7,FALSE),""))) -> 120 | R552: =Q552*(H552/100) -> 0 | S552: =IF(J552="Online Travel Agency",VLOOKUP(F552,room_rates!$A$2:$G$8,3,FALSE)*15%,0) -> 0 | T552: =IF(M552=TRUE, Q552*1%,0) -> 0 | U552: =(Q552-R552-S552-T552)*V552 -> 240 | V552: =K552*P552 -> 2
...

Sheet Date
A1: Date
A2: {=_xlfn.SEQUENCE(MAX(hotel_bookings_data!C:C)-MIN(hotel_bookings_data!C:C)+1,1,MIN(hotel_bookings_data!C:C),1)} -> 45658
A3: 45659
A4: 45660
A5: 45661
A6: 45662
A7: 45663
A8: 45664
A9: 45665
A10: 45666
A11: 45667
A12: 45668
A13: 45669
A14: 45670
... A366: 46022

Sheet ancillary_services
A1: Booking ID | B1: Ancillary Service Type | C1: Service Revenue
A2: 1004256 | B2: Dining | C2: 27
A3: 1004284 | B3: Dining | C3: 27
A4: 1004497 | B4: Spa | C4: 35
A5: 1004498 | B5: Dining | C5: 109
A6: 1004836 | B6: Event | C6: 144
A7: 1005469 | B7: Dining | C7: 61
A8: 1005491 | B8: Event | C8: 197
A9: 1005546 | B9: Dining | C9: 33
A10: 1005586 | B10: Dining | C10: 25
A11: 1005752 | B11: Dining | C11: 79
A12: 1003249 | B12: Event | C12: 140
A13: 1003616 | B13: Event | C13: 477
... A5484: 1005292 | B5484: Spa | C5484: 39

Sheet room_rates
A1: Room Type ID | B1: Room Sub-Type | C1: Base Rate | D1: Peak Season Adjustment Factor | E1: Moderate Season Adjustment Factor | F1: Peak Season Rate | G1: Moderate Season Rate
A2: 6 | B2: Junior Suite | C2: 350 | D2: 1.25 | E2: 1.1 | F2: =room_rates!$C2*room_rates!$D2 -> 437.5 | G2: =room_rates!$C2*room_rates!$E2 -> 385
A3: 3 | B3: Deluxe A | C3: 220 | D3: 1.25 | E3: 1.1 | F3: =room_rates!$C3*room_rates!$D3 -> 275 | G3: =room_rates!$C3*room_rates!$E3 -> 242
A4: 7 | B4: Luxury Suite | C4: 450 | D4: 1.25 | E4: 1.1 | F4: =room_rates!$C4*room_rates!$D4 -> 562.5 | G4: =room_rates!$C4*room_rates!$E4 -> 495
A5: 4 | B5: Deluxe Garden View | C5: 230 | D5: 1.25 | E5: 1.1 | F5: =room_rates!$C5*room_rates!$D5 -> 287.5 | G5: =room_rates!$C5*room_rates!$E5 -> 253
A6: 5 | B6: Deluxe Balcony | C6: 240 | D6: 1.25 | E6: 1.1 | F6: =room_rates!$C6*room_rates!$D6 -> 300 | G6: =room_rates!$C6*room_rates!$E6 -> 264
A7: 1 | B7: Standard Single | C7: 120 | D7: 1.25 | E7: 1.1 | F7: =room_rates!$C7*room_rates!$D7 -> 150 | G7: =room_rates!$C7*room_rates!$E7 -> 132
A8: 2 | B8: Standard Double | C8: 140 | D8: 1.25 | E8: 1.1 | F8: =room_rates!$C8*room_rates!$D8 -> 175 | G8: =room_rates!$C8*room_rates!$E8 -> 154
